/var/spool/slurmd/job7813351/slurm_script: line 15: activate: No such file or directory
Traceback (most recent call last):
  File "/leonardo/home/userexternal/tmencatt/miniconda3/envs/saemerging/lib/python3.12/site-packages/urllib3/connection.py", line 199, in _new_conn
    sock = connection.create_connection(
           ^^^^^^^^^^^^^^^^^^^^^^^^^^^^^
  File "/leonardo/home/userexternal/tmencatt/miniconda3/envs/saemerging/lib/python3.12/site-packages/urllib3/util/connection.py", line 85, in create_connection
    raise err
  File "/leonardo/home/userexternal/tmencatt/miniconda3/envs/saemerging/lib/python3.12/site-packages/urllib3/util/connection.py", line 73, in create_connection
    sock.connect(sa)
OSError: [Errno 101] Network is unreachable

The above exception was the direct cause of the following exception:

Traceback (most recent call last):
  File "/leonardo/home/userexternal/tmencatt/miniconda3/envs/saemerging/lib/python3.12/site-packages/urllib3/connectionpool.py", line 789, in urlopen
    response = self._make_request(
               ^^^^^^^^^^^^^^^^^^^
  File "/leonardo/home/userexternal/tmencatt/miniconda3/envs/saemerging/lib/python3.12/site-packages/urllib3/connectionpool.py", line 490, in _make_request
    raise new_e
  File "/leonardo/home/userexternal/tmencatt/miniconda3/envs/saemerging/lib/python3.12/site-packages/urllib3/connectionpool.py", line 466, in _make_request
    self._validate_conn(conn)
  File "/leonardo/home/userexternal/tmencatt/miniconda3/envs/saemerging/lib/python3.12/site-packages/urllib3/connectionpool.py", line 1095, in _validate_conn
    conn.connect()
  File "/leonardo/home/userexternal/tmencatt/miniconda3/envs/saemerging/lib/python3.12/site-packages/urllib3/connection.py", line 693, in connect
    self.sock = sock = self._new_conn()
                       ^^^^^^^^^^^^^^^^
  File "/leonardo/home/userexternal/tmencatt/miniconda3/envs/saemerging/lib/python3.12/site-packages/urllib3/connection.py", line 214, in _new_conn
    raise NewConnectionError(
urllib3.exceptions.NewConnectionError: <urllib3.connection.HTTPSConnection object at 0x14eaf639d4c0>: Failed to establish a new connection: [Errno 101] Network is unreachable

The above exception was the direct cause of the following exception:

Traceback (most recent call last):
  File "/leonardo/home/userexternal/tmencatt/miniconda3/envs/saemerging/lib/python3.12/site-packages/requests/adapters.py", line 667, in send
    resp = conn.urlopen(
           ^^^^^^^^^^^^^
  File "/leonardo/home/userexternal/tmencatt/miniconda3/envs/saemerging/lib/python3.12/site-packages/urllib3/connectionpool.py", line 843, in urlopen
    retries = retries.increment(
              ^^^^^^^^^^^^^^^^^^
  File "/leonardo/home/userexternal/tmencatt/miniconda3/envs/saemerging/lib/python3.12/site-packages/urllib3/util/retry.py", line 519, in increment
    raise MaxRetryError(_pool, url, reason) from reason  # type: ignore[arg-type]
    ^^^^^^^^^^^^^^^^^^^^^^^^^^^^^^^^^^^^^^^^^^^^^^^^^^^
urllib3.exceptions.MaxRetryError: HTTPSConnectionPool(host='huggingface.co', port=443): Max retries exceeded with url: /google/gemma-2b/resolve/main/config.json (Caused by NewConnectionError('<urllib3.connection.HTTPSConnection object at 0x14eaf639d4c0>: Failed to establish a new connection: [Errno 101] Network is unreachable'))

During handling of the above exception, another exception occurred:

Traceback (most recent call last):
  File "/leonardo/home/userexternal/tmencatt/miniconda3/envs/saemerging/lib/python3.12/site-packages/huggingface_hub/file_download.py", line 1746, in _get_metadata_or_catch_error
    metadata = get_hf_file_metadata(
               ^^^^^^^^^^^^^^^^^^^^^
  File "/leonardo/home/userexternal/tmencatt/miniconda3/envs/saemerging/lib/python3.12/site-packages/huggingface_hub/utils/_validators.py", line 114, in _inner_fn
    return fn(*args, **kwargs)
           ^^^^^^^^^^^^^^^^^^^
  File "/leonardo/home/userexternal/tmencatt/miniconda3/envs/saemerging/lib/python3.12/site-packages/huggingface_hub/file_download.py", line 1666, in get_hf_file_metadata
    r = _request_wrapper(
        ^^^^^^^^^^^^^^^^^
  File "/leonardo/home/userexternal/tmencatt/miniconda3/envs/saemerging/lib/python3.12/site-packages/huggingface_hub/file_download.py", line 364, in _request_wrapper
    response = _request_wrapper(
               ^^^^^^^^^^^^^^^^^
  File "/leonardo/home/userexternal/tmencatt/miniconda3/envs/saemerging/lib/python3.12/site-packages/huggingface_hub/file_download.py", line 387, in _request_wrapper
    response = get_session().request(method=method, url=url, **params)
               ^^^^^^^^^^^^^^^^^^^^^^^^^^^^^^^^^^^^^^^^^^^^^^^^^^^^^^^
  File "/leonardo/home/userexternal/tmencatt/miniconda3/envs/saemerging/lib/python3.12/site-packages/requests/sessions.py", line 589, in request
    resp = self.send(prep, **send_kwargs)
           ^^^^^^^^^^^^^^^^^^^^^^^^^^^^^^
  File "/leonardo/home/userexternal/tmencatt/miniconda3/envs/saemerging/lib/python3.12/site-packages/requests/sessions.py", line 703, in send
    r = adapter.send(request, **kwargs)
        ^^^^^^^^^^^^^^^^^^^^^^^^^^^^^^^
  File "/leonardo/home/userexternal/tmencatt/miniconda3/envs/saemerging/lib/python3.12/site-packages/huggingface_hub/utils/_http.py", line 93, in send
    return super().send(request, *args, **kwargs)
           ^^^^^^^^^^^^^^^^^^^^^^^^^^^^^^^^^^^^^^
  File "/leonardo/home/userexternal/tmencatt/miniconda3/envs/saemerging/lib/python3.12/site-packages/requests/adapters.py", line 700, in send
    raise ConnectionError(e, request=request)
requests.exceptions.ConnectionError: (MaxRetryError("HTTPSConnectionPool(host='huggingface.co', port=443): Max retries exceeded with url: /google/gemma-2b/resolve/main/config.json (Caused by NewConnectionError('<urllib3.connection.HTTPSConnection object at 0x14eaf639d4c0>: Failed to establish a new connection: [Errno 101] Network is unreachable'))"), '(Request ID: beae2ac0-06a3-4583-9eb4-653671de19de)')

The above exception was the direct cause of the following exception:

Traceback (most recent call last):
  File "/leonardo/home/userexternal/tmencatt/miniconda3/envs/saemerging/lib/python3.12/site-packages/transformers/utils/hub.py", line 402, in cached_file
    resolved_file = hf_hub_download(
                    ^^^^^^^^^^^^^^^^
  File "/leonardo/home/userexternal/tmencatt/miniconda3/envs/saemerging/lib/python3.12/site-packages/huggingface_hub/utils/_deprecation.py", line 101, in inner_f
    return f(*args, **kwargs)
           ^^^^^^^^^^^^^^^^^^
  File "/leonardo/home/userexternal/tmencatt/miniconda3/envs/saemerging/lib/python3.12/site-packages/huggingface_hub/utils/_validators.py", line 114, in _inner_fn
    return fn(*args, **kwargs)
           ^^^^^^^^^^^^^^^^^^^
  File "/leonardo/home/userexternal/tmencatt/miniconda3/envs/saemerging/lib/python3.12/site-packages/huggingface_hub/file_download.py", line 1232, in hf_hub_download
    return _hf_hub_download_to_cache_dir(
           ^^^^^^^^^^^^^^^^^^^^^^^^^^^^^^
  File "/leonardo/home/userexternal/tmencatt/miniconda3/envs/saemerging/lib/python3.12/site-packages/huggingface_hub/file_download.py", line 1339, in _hf_hub_download_to_cache_dir
    _raise_on_head_call_error(head_call_error, force_download, local_files_only)
  File "/leonardo/home/userexternal/tmencatt/miniconda3/envs/saemerging/lib/python3.12/site-packages/huggingface_hub/file_download.py", line 1857, in _raise_on_head_call_error
    raise LocalEntryNotFoundError(
huggingface_hub.errors.LocalEntryNotFoundError: An error happened while trying to locate the file on the Hub and we cannot find the requested files in the local cache. Please check your connection and try again or make sure your Internet connection is on.

The above exception was the direct cause of the following exception:

Traceback (most recent call last):
  File "/leonardo_work/IscrC_MGNTC/tmencatt/SAE-Tuning-Merging/experiments/1.0-sae-eval/eval_sae.py", line 25, in <module>
    compute_scores(cfg)
  File "/leonardo_work/IscrC_MGNTC/tmencatt/SAE-Tuning-Merging/saetuning/get_scores.py", line 303, in compute_scores
    base_model = HookedSAETransformer.from_pretrained(cfg.BASE_MODEL, device=device, dtype=cfg.DTYPE)
                 ^^^^^^^^^^^^^^^^^^^^^^^^^^^^^^^^^^^^^^^^^^^^^^^^^^^^^^^^^^^^^^^^^^^^^^^^^^^^^^^^^^^^
  File "/leonardo/home/userexternal/tmencatt/miniconda3/envs/saemerging/lib/python3.12/site-packages/transformer_lens/HookedTransformer.py", line 1298, in from_pretrained
    state_dict = loading.get_pretrained_state_dict(
                 ^^^^^^^^^^^^^^^^^^^^^^^^^^^^^^^^^^
  File "/leonardo/home/userexternal/tmencatt/miniconda3/envs/saemerging/lib/python3.12/site-packages/transformer_lens/loading_from_pretrained.py", line 1672, in get_pretrained_state_dict
    hf_model = AutoModelForCausalLM.from_pretrained(
               ^^^^^^^^^^^^^^^^^^^^^^^^^^^^^^^^^^^^^
  File "/leonardo/home/userexternal/tmencatt/miniconda3/envs/saemerging/lib/python3.12/site-packages/transformers/models/auto/auto_factory.py", line 524, in from_pretrained
    config, kwargs = AutoConfig.from_pretrained(
                     ^^^^^^^^^^^^^^^^^^^^^^^^^^^
  File "/leonardo/home/userexternal/tmencatt/miniconda3/envs/saemerging/lib/python3.12/site-packages/transformers/models/auto/configuration_auto.py", line 976, in from_pretrained
    config_dict, unused_kwargs = PretrainedConfig.get_config_dict(pretrained_model_name_or_path, **kwargs)
                                 ^^^^^^^^^^^^^^^^^^^^^^^^^^^^^^^^^^^^^^^^^^^^^^^^^^^^^^^^^^^^^^^^^^^^^^^^^
  File "/leonardo/home/userexternal/tmencatt/miniconda3/envs/saemerging/lib/python3.12/site-packages/transformers/configuration_utils.py", line 632, in get_config_dict
    config_dict, kwargs = cls._get_config_dict(pretrained_model_name_or_path, **kwargs)
                          ^^^^^^^^^^^^^^^^^^^^^^^^^^^^^^^^^^^^^^^^^^^^^^^^^^^^^^^^^^^^^
  File "/leonardo/home/userexternal/tmencatt/miniconda3/envs/saemerging/lib/python3.12/site-packages/transformers/configuration_utils.py", line 689, in _get_config_dict
    resolved_config_file = cached_file(
                           ^^^^^^^^^^^^
  File "/leonardo/home/userexternal/tmencatt/miniconda3/envs/saemerging/lib/python3.12/site-packages/transformers/utils/hub.py", line 445, in cached_file
    raise EnvironmentError(
OSError: We couldn't connect to 'https://huggingface.co' to load this file, couldn't find it in the cached files and it looks like google/gemma-2b is not the path to a directory containing a file named config.json.
Checkout your internet connection or see how to run the library in offline mode at 'https://huggingface.co/docs/transformers/installation#offline-mode'.
